Workbook
Name ApplicationProfile: List!$E$2:$E$30
Name isAdopted: List!$A$2:$A$11
Name Ontology: List!$B$2:$B$11
Name Predicate: List!$F$2:$F$11
Name Source: List!$D$2:$D$11
Name Type: List!$C$2:$C$11

Sheet Intro
A1: When to use this document? | B1: The Federal Vocabularies (FedVoc) describe semantics in domains commonly used by Belgian government institutions. You can use them • during business analysis, when designing the data model of an application or • when authoring specifications of an API or webservice (OpenAPI, WSDL/XSD, ...). If you can't find a concept that's commonly used by Belgian government institutions, you may open an issue (https://github.com/belgif/fedvoc/issues) to request the concept to be added.
A3: How to read this document? | B3: Explanation of the sheets:
A4: Standard | B4: In the "Standard" sheet, you find the vocabulary entries accepted by the Federal government as standard vocabulary. The column ‘Ontology’ gives the different domains covered by the vocabulary. To find entries more easily, you can filter on ‘Ontology’ or do a full search (Ctrl+F). * The column ‘Name’ provides a short name of the vocabulary entry. It should be used as the basis of technical names for the entry, for instance when the item is used in a REST APIs. * The columns ‘LabelNL’ and ‘LabelFR’ provide translations of this ‘Name’. * The columns ‘Definition’ (DefinitionNL/DefinitionFR) specify a, preferably concise, definition of the entry * The columns ‘Comment’ (CommentNL/CommentFR) may provide additional information * The column ‘inOpenApi’ indicates if the entry has a corresponding OpenAPI data type
A5: Draft | B5: In the "Draft" sheet, you find the vocabulary entries that are still a work in progress.
A6: ChangeLog | B6: In this sheet you can find an overview of changes made to fedvoc.
A7: Government institutions | B7: The “Government institutions” sheet provides the common names for Belgian Government institutions (code = abbreviation, name = full name, status = Draft/Standard)
A8: Vocabulary | B8: The vocabularies coming from 3 sources are present here: Federal Government Services, Flanders, EU The following ontologies are present: Person, Organization, Location, Temporal, Generic, Other Each vocabulary element has a numeric identifier (no meaning attached), a name (camelcase, English) and a definition. A prefix pointing towards the source and the ontology has been defined so that a unique identifier (URI) can be produced. Each vocabulary element has a type associated to it: class, property, association (property linking 2 classes) and conceptscheme. The sheet also contains a column for optional comment.
A9: VocabularyNL | B9: A label and a definition in NL are added to each of the vocabulary elements of sheet Vocabulary.
A10: VocabularyFR | B10: A label and a definition in FR are added to each of the vocabulary elements of sheet Vocabulary.
A11: VocabularyTranslations | B11: This sheet displays the vocabulary elements and definitions in English, Dutch and French. (display only, no updates here)
A12: VocabularyMapping | B12: For each vocabulary element of sheet "Vocabulary" you can find here the links ("sameAs") to vocabulary elements of other sources. E.g. for a vocabulary element defined at federal level, you can see here the corresponding vocabulary elements, if any, defined by EU and by Flanders.
A13: VocabularyAdoption | B13: For each of the vocabulary elements in sheet "Vocabulary" you can find here which elements have been adopted by the various parties such as EU, Federal level, Flanders, Walloon, Brussels, French community, German community. Possible values are: draft, proposed standard, standard
... A16: Principles followed by the workgroup: | B16: The workgroup tries to reuse as much as possible existing vocabularies in order to allocate names, URI's and defintions to vocabulary items. In order of importance, the following priorities are respected: first European vocabularies, then international vocabularies and finally self-defined vocabularies.
B18: US-English or UK-English ? If there is a clear EU/international vocabulary, we use the English terminology used in this standard according to the priorities listed previously. If not, by default US-English will be preferred.
B19: The workgroup also tries to respect the ICEG-standard on URI's that can be found at https://github.com/belgif/thematic/blob/master/URI/iceg_uri_standard.md

Sheet Standard
A1: Id | B1: Source | C1: Ontology | D1: Type | E1: URI | F1: Name | G1: LabelNL | H1: LabelFR | I1: Definition | J1: DefinitionNL | K1: DefinitionFR | L1: Comment | M1: CommentNL | N1: CommentFR | O1: inOpenApi
A2: 101 | B2: EU | C2: Organization | D2: Class | E2: <eu:LegalEntity> | F2: LegalEntity | G2: Rechtspersoon | H2: Personne morale | I2: A self-employed person, company, or organization that has legal rights and obligations. | J2: Een zelfstandige, bedrijf of organisatie met wettelijke rechten en plichten. | K2: Une personne, une entreprise ou une organisation indépendante qui a des droits et des obligations juridiques. | L2: A Legal Entity able to transact business, typically registered with a body able to confer legal status such as a national business register. It is able to trade, is legally liable for its actions, accounts, tax affairs etc. This makes Legal Entities distinct from the concept of organisations or groups. Many organisations exist that are not Legal Entities, yet to the outside world they have staff, hierarchies, locations etc. Other organisations exist that are an umbrella for several Legal Entities (universities are often good examples of this). This vocabulary is concerned solely with registered Legal Entities and does not attempt to cover all possible trading bodies. Belgian legal entities are registered in CBE and have an enterprise number. | M2: Een rechtspersoon die zaken kan doen, doorgaans geregistreerd bij een instantie die een wettelijke status kan verlenen, zoals een nationaal bedrijfsregister. Het kan handelen, is wettelijk aansprakelijk voor zijn acties, rekeningen, belastingzaken, enz. Dit onderscheidt rechtspersonen van het concept van organisaties of groepen. Er bestaan ​​veel organisaties die geen rechtspersonen zijn, maar voor de buitenwereld hebben ze personeel, hiërarchieën, locaties, enz. Er bestaan ​​ook andere organisaties die een paraplu vormen voor verschillende rechtspersonen (universiteiten zijn hier vaak goede voorbeelden van). Deze woordenschat heeft uitsluitend betrekking op geregistreerde rechtspersonen en probeert niet alle mogelijke handelslichamen te dekken. Belgische rechtspersonen worden ingeschreven in de KBO en beschikken over een ondernemingsnummer. | N2: Entité juridique en mesure de réaliser des transactions commerciales, généralement enregistrée auprès d'un organisme habilité à lui conférer un statut juridique, tel qu'un registre national des entreprises. Elle est en mesure de faire du commerce, est juridiquement responsable de ses actes, de ses comptes, de ses affaires fiscales, etc. Cela distingue les entités juridiques du concept d'organisations ou de groupes. De nombreuses organisations ne sont pas des entités juridiques, mais elles ont, aux yeux du monde extérieur, du personnel, des hiérarchies, des locaux, etc. D'autres organisations regroupent plusieurs entités juridiques (les universités en sont souvent de bons exemples). Ce vocabulaire concerne uniquement les entités juridiques enregistrées et ne tente pas de couvrir tous les organismes commerciaux possibles. Les personnes morales belges sont enregistrées à la BCE et disposent d'un numéro d'entreprise. | O2: no
A3: 220 | B3: FED | C3: Organization | D3: Class | E3: <http://www.w3.org/ns/org#OrganizationalUnit> | F3: OrganizationalUnit | G3: Organisatie-eenheid | H3: Unité organisationnelle | I3: An Organization such as a department or support unit which is part of some larger Organization and only has full recognition within the context of that Organization. In particular the unit would not be regarded as a legal entity in its own right. | J3: Een organisatie zoals een afdeling of ondersteuningseenheid die deel uitmaakt van een grotere organisatie en alleen volledige erkenning heeft binnen de context van die organisatie. In het bijzonder zou de eenheid niet als een op zichzelf staande juridische entiteit worden beschouwd. | K3: Une organisation telle qu'un département ou une unité de soutien qui fait partie d'une organisation plus grande et qui n'est pleinement reconnue que dans le contexte de cette organisation. En particulier, l'unité ne serait pas considérée comme une entité juridique à part entière. | O3: no
A4: 221 | B4: FED | C4: Organization | D4: Class | E4: <http://www.w3.org/ns/org#Organization> | F4: Organization | G4: Organisatie | H4: Organisation | I4: Represents a collection of people organized together into a community or other social, commercial or political structure. The group has some common purpose or reason for existence which goes beyond the set of people belonging to it and can act as an Agent. Organizations are often decomposable into hierarchical structures. | J4: Vertegenwoordigt een verzameling mensen die samen zijn georganiseerd in een gemeenschap of een andere sociale, commerciële of politieke structuur. De groep heeft een gemeenschappelijk doel of reden van bestaan die verder gaat dan de groep mensen die erbij horen en kan optreden als een agent. Organisaties zijn vaak te ontleden in hiërarchische structuren. | K4: Représente une collection de personnes organisées ensemble dans une communauté ou une autre structure sociale, commerciale ou politique. Le groupe a un objectif commun ou une raison d'existence qui dépasse le nombre de personnes qui lui appartiennent et peut agir en tant qu'agent. Les organisations sont souvent décomposables en structures hiérarchiques. | O4: no
A5: 222 | B5: FED | C5: Organization | D5: Class | E5: <http://data.europa.eu/m8g/PublicOrganization> | F5: PublicOrganization | G5: Publieke Organisatie | H5: Organisation publique | I5: The Public Organization class represents the organization. One organization may comprise several sub-organizations and any organization may have one or more organizational units. In some cases, albeit rare ones, a Public Organization may not be a legal entity. | J5: De klasse Public Organization vertegenwoordigt de organisatie. Eén organisatie kan meerdere suborganisaties omvatten en elke organisatie kan een of meer organisatie-eenheden hebben. In sommige gevallen, zij het zeldzame, is een openbare organisatie mogelijk geen rechtspersoon. | K5: La classe Organisation publique représente l'organisation. Une organisation peut comprendre plusieurs sous-organisations et toute organisation peut avoir une ou plusieurs unités organisationnelles. Dans certains cas, même rares, une organisation publique peut ne pas être une entité juridique. | O5: no
A6: 223 | B6: FED | C6: Organization | D6: Property | E6: <https://w3id.org/i40/sto#abbreviation> | F6: abbreviatedName | G6: Afgekorte naam | H6: Nom abrégé | I6: Abbreviated name of the thing. | J6: Afgekorte naam. | K6: Nom abrégé. | L6: Abbreviated name of an organization or site. | M6: Afgekorte naam van een organisatie of een site. | N6: Nom abrégé d'une organisation ou d'un site. | O6: no
A7: 224 | B7: FED | C7: Location | D7: Property | E7: <http://www.w3.org/ns/locn#address> | F7: address | G7: Adres | H7: Adresse | I7: Identification of a location. | J7: Identificatie van een locatie. | K7: Identification d'un lieu. | O7: no
A8: 226 | B8: FED | C8: Organization | D8: Property | E8: <altLabel> | F8: commercialName | G8: Handelsnaam | H8: Dénomination commerciale | I8: Alternative label | J8: Alternatieve naam. | K8: Nom alternatif. | L8: A recognized name other than the legal name. | M8: Een erkende naam anders dan de wettelijke naam. | N8: Un nom reconnu autre que le nom légal. | O8: no
A9: 227 | B9: FED | C9: Organization | D9: Property | E9: <http://vocab.belgif.be/ns/organization#economicActivity> | F9: economicActivity | G9: Economische activiteit | H9: Activité économique | I9: The activity of the business. | J9: De economische activiteit van de business. | K9: L'activité économique du business. | L9: See rov:orgActivity (673) | M9: Zie rov:orgActivity (673) | N9: Voir rov:orgActivity (673) | O9: no
A10: 228 | B10: FED | C10: Organization | D10: Property | E10: <http://schema.org/email> | F10: email | G10: E-mail | H10: E-mail | I10: E-mail address. | J10: E-mail adres. | K10: Adresse e-mail. | O10: no
A11: 230 | B11: FED | C11: Organization | D11: Property | E11: <http://vocab.belgif.be/ns/organization#endReason> | F11: endReason | G11: Reden stopzetting | H11: Raison d'arrêt | I11: Reason why an organization or one of its sites has been stopped. | J11: Reden weer waarom een onderneming of één van zijn vestigingseenheden is gestopt. | K11: Raison pour laquelle une entreprise ou une de ses unités d'établissement a été arrêtée. | O11: no
A12: 231 | B12: FED | C12: Organization | D12: Property | E12: <identifier> | F12: enterpriseNumber | G12: Ondernemingsnummer | H12: Numéro d'entreprise | I12: Identifier issued by CBE for a registered organization | J12: Identifier toegekend door KBO aan een geregistreerde organisatie | K12: Identifiant attribué par la BCE à une organisation enregistrée | L12: CBE = Crossroads Bank for Enterprises | M12: KBO = KruispuntBank Ondernemingen | N12: BCE = Banque Carrefour des Entreprises | O12: yes
A13: 232 | B13: FED | C13: Organization | D13: Property | E13: <identifier> | F13: establishmentUnitNumber | G13: Vestigingseenheidsnummer | H13: Numéro d'unité d'établissement | I13: Identifier issued by CBE for a site (establishment) of an organization | J13: Identifier toegekend door KBO voor een vestigingseenheid van een organisatie. | K13: Identifiant attribué par la BCE pour une unité d'établissement d'une organisation | L13: CBE = Crossroads Bank for Enterprises | M13: KBO = KruispuntBank Ondernemingen | N13: BCE = Banque Carrefour des Entreprises | O13: yes
A14: 233 | B14: FED | C14: Organization | D14: Property | E14: <http://schema.org/faxNumber> | F14: faxNumber | G14: Fax-nummer | H14: Numéro de fax | I14: Fax number. | J14: Fax nummer. | K14: Numéro de fax. | O14: no
A15: 235 | B15: FED | C15: Organization | D15: Property | E15: <org:role> | F15: function | G15: Functie | H15: Fonction | I15: Role played by a person or an organization in a given organization. E.g. founder, manager, member of the management committee, ... | J15: Rol gespeeld door een persoon of organisatie in een bepaalde organisatie. Bijv. oprichter, manager, lid van het managementcomité, ... | K15: Rôle joué par une personne ou une organisation dans une organisation donnée. Par exemple: fondateur, dirigeant, membre du comité de direction, ... | O15: no
A16: 236 | B16: FED | C16: Organization | D16: Property | E16: <http://www.w3.org/ns/org#hasEstablishmentUnit> | F16: hasEstablishmentUnit | G16: Heeft vestigingseenheid | H16: A une unité d'établissement | I16: Organizations typically comprise many departments, units, teams ... 'hasEstablishmentUnit' links the parent organization with the underlying unit. | J16: Organisaties bestaan doorgaans uit vele afdelingen, eenheden, teams ... 'hasEstablishmentUnit' verbindt de moederorganisatie met de onderliggende eenheid. | K16: Les organisations comprennent généralement de nombreux départements, unités, équipes ... 'hasEstablishmentUnit' relie l'organisation parente à l'unité sous-jacente. | O16: no
A17: 237 | B17: FED | C17: Organization | D17: Property | E17: <http://www.w3.org/ns/regorg#legalForm> | F17: legalForm | G17: Rechtsvorm | H17: Forme juridique | I17: "legalForm" indicates the type of company that can be established by legal entities and companies without legal personality. The different legal forms for companies set up by legal entities are usually determined by law. Legal forms are maintained for companies without legal personality. An enterprise natural person has no legal form. A legal entity or company without legal personality may change over time from a legal form. | J17: "Rechtsvorm" duidt het soort onderneming aan dat kan opgericht worden door rechtspersonen en ondernemingen zonder rechtspersoonlijkheid. De verschillende rechtsvormen voor ondernemingen opgericht door rechtspersonen zijn meestal bij wet bepaald. Voor ondernemingen zonder rechtspersoonlijkheid worden rechtsvormen bijgehouden. Een onderneming natuurlijke persoon heeft geen rechtsvorm. Een onderneming rechtspersoon of een onderneming zonder rechtpersoonlijkheid kunnen in de loop der tijd veranderen van rechtsvorm. | K17: "Forme juridique" indique le type de société pouvant être créée par des personnes morales et des sociétés sans personnalité juridique. Les différentes formes juridiques des sociétés créées par des personnes morales sont généralement déterminées par la loi. Pour les entreprises sans personnalité juridique, les formes juridiques sont maintenues. Une entreprise personne physique n'a pas de forme juridique. Une personne morale ou une entreprise sans personnalité juridique peut changer au fil du temps d’une forme juridique. | L17: Specialization of <http://www.w3.org/ns/regorg#orgType>. | M17: Specialisatie van <http://www.w3.org/ns/regorg#orgType>. | N17: Spécialisation de <http://www.w3.org/ns/regorg#orgType>. | O17: no
A18: 238 | B18: FED | C18: Organization | D18: Property | E18: <http://www.w3.org/ns/regorg#legalName> | F18: legalName | G18: Maatschappelijke naam | H18: Dénomination sociale | I18: The legal name of the business. | J18: De wettelijke naam van het bedrijf. | K18: Le nom légal de l'entreprise. | L18: (CBE Oct 2018): there will no longer be spoken of social address, social name and social capital but of address, name and capital. | M18: (KBO okt. 2018): er wordt niet langer gesproken over sociaal adres, sociale naam en sociaal kapitaal, maar over adres, naam en kapitaal. | N18: (BCE oct 2018): on ne parlera plus d'adresse sociale, de nom social et de capital social mais d'adresse, de nom et de capital. | O18: no
A19: 239 | B19: FED | C19: Organization | D19: Property | E19: <http://vocab.belgif.be/ns/organization#legalStatus> | F19: legalStatus | G19: Rechtsstatus | H19: Statut légal | I19: The legal status of the registered organization. E.g. normal situation, judicial agreement, opening bankruptcy etc. | J19: De wettelijke status van de geregistreerde organisatie. Bijv. normale situatie, gerechtelijke overeenkomst, opening faillissement etc. | K19: Le statut légal de l'organisation enregistrée. Par exemple: situation normale, accord judiciaire, mise en faillite, etc. | O19: no
A20: 242 | B20: FED | C20: Organization | D20: Property | E20: <http://vocab.belgif.be/ns/organization#organizationType> | F20: organizationType | G20: Organisatietype | H20: Type d'organisation | I20: Type of organization: -natural person or -legal entity/undertaking without legal personality. | J20: Type organisatie: -natuurlijk persoon of -rechtspersoon/onderneming zonder rechtspersoonlijkheid. | K20: Type d'organisation: - une entreprise personne physique ou -une personne morale/entreprise sans personnalité juridique. | O20: no
A21: 244 | B21: FED | C21: Organization | D21: Property | E21: <http://vocab.belgif.be/ns/organization#naturalPerson> | F21: naturalPerson | G21: Natuurlijke persoon | H21: Personne physique | I21: Natural person. | J21: Natuurlijke persoon | K21: Personne physique | O21: no
A22: 245 | B22: FED | C22: Organization | D22: Property | E22: <http://schema.org/telephone> | F22: telephone | G22: Telefoonnummer | H22: Numéro de téléphone | I22: Telephone number. | J22: Telefoonnummer | K22: Numéro de téléphone | L22: Pattern: ^\+[1-9]\d{1,14}$ | M22: Pattern: ^\+[1-9]\d{1,14}$ | N22: Pattern: ^\+[1-9]\d{1,14}$ | O22: no
A23: 248 | B23: FED | C23: Organization | D23: Property | E23: <foaf:homepage> | F23: website | G23: Website | H23: Site web | I23: Website. | J23: Website. | K23: Site web. | O23: no
A24: 249 | B24: FED | C24: Location | D24: Class | E24: <Address> | F24: BelgianAddress | G24: Belgisch adres | H24: Adresse belge | I24: An "address representation" as conceptually defined by the INSPIRE Address Representation data type. | J24: Een "adresrepresentatie" zoals conceptueel gedefinieerd door het gegevenstype INSPIRE Address Representation. | K24: Une "représentation d'adresse" définie conceptuellement par le type de données INSPIRE Address Representation. | L24: A Belgian address representing a location. Information that makes it possible to refer in a structured and unique way to a building unit, a mooring place, a stand or a parcel based on a town name, a street name, a house number and possibly a bus number and a postcode. Alternative address designations other than house number or bus number (eg entrance indication, staircase display, floor display ...) or a building name or room name, etc. are possible through an association with address extension. Exchange of foreign addresses must be done using the address presentation object. | M24: Een Belgisch adres dat een locatie vertegenwoordigt. Informatie die het mogelijk maakt om op een gestructureerde en unieke manier naar een gebouweenheid, een ligplaats, een stand of een perceel te verwijzen op basis van de naam van een stad, een straatnaam, een huisnummer en eventueel een busnummer en een postcode. Alternatieve adresaanduidingen anders dan huisnummer of busnummer (bijv. Ingangsindicatie, trappenhuisweergave, vloerdisplay ...) of een naam van een gebouw of een kamer, enz. Zijn mogelijk via een koppeling met adresuitbreiding. Het uitwisselen van buitenlandse adressen moet gebeuren met behulp van het adrespresentatieobject. | N24: Une adresse belge représentant un emplacement. Informations permettant de faire référence de manière structurée et unique à un bâtiment, un lieu d'amarrage, un stand ou une parcelle en fonction d'un nom de ville, d'un nom de rue, d'un numéro de maison et éventuellement d'un numéro de bus et d'un code postal. Des noms d'adresse autres que le numéro de maison ou le numéro de bus (par exemple, indication d'entrée, affichage d'escalier, affichage au sol ...) ou un nom de bâtiment ou de chambre, etc. sont possibles via une association avec extension d'adresse. L'échange d'adresses étrangères doit être effectué à l'aide de l'objet de présentation d'adresse. | O24: no
A25: 250 | B25: FED | C25: Location | D25: Class | E25: <http://vocab.belgif.be/ns/location#AddressableObject> | F25: AddressableObject | G25: Adresseerbaar object | H25: Objet addressable | I25: Geographical object that can be identified with an address. Is abstract, ie the type of addressable object must always be specified (e.g. building unit, parcel, ..). | J25: Geografisch object dat kan worden geïdentificeerd met een adres. Is abstract, dwz het type adresseerbaar object moet altijd worden gespecificeerd (bijv. Gebouweenheid, perceel, ..). | K25: Objet géographique pouvant être identifié avec une adresse. Est abstrait, c'est-à-dire que le type d'objet adressable doit toujours être spécifié (par exemple: unité de construction, parcelle, ..). | O25: no
A26: 251 | B26: FED | C26: Location | D26: Class | E26: <Address> | F26: Address | G26: Adres | H26: Adresse | I26: An address is an identification of the fixed location of a property. The full address is a hierarchy consisting of components such as geographic names, with an increasing level of detail, e.g. town, then street name, then house number or name. It may also include a post code or other postal descriptors. The address may include a path of access but this depends on the function of the address. | J26: Een adres is een identificatie van de vaste locatie van een goed. Het volledige adres is een hiërarchie die bestaat uit componenten zoals geografische namen, met een toenemend detailniveau, b.v. plaats, dan straatnaam, dan huisnummer of naam. Het kan ook een postcode of andere postbeschrijvingen bevatten. Het adres kan een toegangspad bevatten, maar dit is afhankelijk van de functie van het adres. | K26: Une adresse est une identification de l’emplacement fixe d’une propriété. L'adresse complète est une hiérarchie composée de composants tels que des noms géographiques, avec un niveau de détail croissant, par ex. ville, puis nom de la rue, puis numéro ou nom de la maison. Il peut également inclure un code postal ou d'autres descripteurs postaux. L'adresse peut inclure un chemin d'accès mais cela dépend de la fonction de l'adresse. | L26: An "address representation" as conceptually defined by the INSPIRE Address Representation data type. https://github.com/INSPIRE-MIF/technical-guidelines/blob/main/data/ad/dataspecification_ad.pdf (§2.2) (§2.2) | M26: Een "adresrepresentatie" zoals conceptueel gedefinieerd door het gegevenstype INSPIRE Address Representation. https://github.com/INSPIRE-MIF/technical-guidelines/blob/main/data/ad/dataspecification_ad.pdf (§2.2) | N26: Une "représentation d'adresse" définie conceptuellement par le type de données INSPIRE Address Representation. https://github.com/INSPIRE-MIF/technical-guidelines/blob/main/data/ad/dataspecification_ad.pdf (§2.2) (§2.2) | O26: no
A27: 252 | B27: FED | C27: Location | D27: Class | E27: <http://vocab.belgif.be/ns/location#BuildingUnit> | F27: BuildingUnit | G27: Gebouw | H27: Batiment | I27: The smallest unit within a building that is suitable for residential, commercial or recreational purposes and that can be accessed via its own lockable access from the public road, a yard or a common room. | J27: De kleinste eenheid binnen een gebouw die geschikt is voor woon-,bedrijfsmatige,of recreatieve doeleinden en die ontsloten wordt via een eigen afsluitbare toegang vanaf de openbare weg,een erf of een gemeenschappelijke ruimte. | K27: La plus petite unité à l’intérieur d’un bâtiment convenant à des fins d’habitation,d’entreprise ou de récréation et qui est rendue accessible par le biais de son propre accès délimitable à partir de la voie publique,d’un terrain ou d’un espace commun. | O27: no
A28: 255 | B28: FED | C28: Location | D28: Class | E28: <GeographicPosition> | F28: GeographicPosition | G28: Geografische positie | H28: Position géographique | I28: Geographic position indicated by a point. | J28: Geografische positie aangegeven dmv een punt. | K28: Position géographique indiquée par un point. | O28: no
A29: 256 | B29: FED | C29: Generic | D29: Class | E29: <http://www.w3.org/ns/adms#Identifier> | F29: Identifier | G29: Identifier (complex) | H29: Identifiant (complexe) | I29: This class is based on the UN/CEFACT Identifier complex type defined in See Section 5.8 of Core Components Data Type Catalogue Version 3.1 (http://www.unece.org/fileadmin/DAM/cefact/codesfortrade/CCTS/CCTS-DTCatalogueVersion3p1.pdf) In RDF this is expressed using the following properties: - the content string should be provided using skos:notation, datatyped with the identifier scheme (including the version number if appropriate); - use dcterms:creator to link to a class describing the agency that manages the identifier scheme or adms:schemaAgency to provide the name as a literal. Although not part of the ADMS conceptual model, it may be useful to provide further properties to the Identifier class such as dcterms:created to provide the date on which the identifier was issued. | J29: Deze klasse is gebaseerd op het type UN / CEFACT Identifier-complex dat is gedefinieerd in Zie sectie 5.8 van Core-componenten gegevenstype catalogusversie 3.1 (http://www.unece.org/fileadmin/DAM/cefact/codesfortrade/CCTS/CCTS-DTCatalogueVersion3p1. pdf) In RDF wordt dit uitgedrukt met behulp van de volgende eigenschappen: - de inhoudstring moet worden verstrekt met gebruik van skos:notatie, datatype met het identificatieschema (inclusief het versienummer, indien van toepassing); - gebruik dcterms:creator om te linken naar een klasse die het bureau beschrijft dat het identificatieschema beheert of adms:schemaAgency om de naam als een letterlijke naam te geven. Hoewel het geen deel uitmaakt van het ADMS-conceptuele model, kan het nuttig zijn om verdere eigenschappen aan te brengen in de klasse Identifier, zoals dcterms:created om de datum op te geven waarop de identifier is uitgegeven. | K29: Cette classe est basée sur le type complexe d'identifiant CEFACT-ONU défini dans Voir la section Section 5.8 du Catalogue de types de données des composants centraux, version 3.1 (http://www.unece.org/fileadmin/DAM/cefact/codesfortrade/CCTS/CCTS-DTCatalogueVersion3p1. pdf) En RDF, cela est exprimé à l'aide des propriétés suivantes: - la chaîne de contenu doit être fournie en utilisant skos:notation, dactylographiée avec le schéma d'identificateur (y compris le numéro de version, le cas échéant); - use dcterms:creator pour se connecter à une classe décrivant l'agence qui gère le schéma d'identificateur ou adms:schemaAgency pour fournir le nom sous forme littérale. Bien que cela ne fasse pas partie du modèle conceptuel ADMS, il peut être utile de fournir des propriétés supplémentaires à la classe Identifier, telles que dcterms:created pour fournir la date à laquelle l'identifiant a été émis. | O29: no
A30: 257 | B30: FED | C30: Location | D30: Class | E30: <http://vocab.belgif.be/ns/location#MooringPlace> | F30: MooringPlace | G30: Aanlegplaats | H30: Amarrage | I30: A specifically designated place in the water, whether or not supplemented by a piece of land or a piece of land on the bank, allocated by the competent communal body and intended for the permanent anchorage of a vessel suitable for residential, commercial and recreational purposes | J30: Een door het bevoegde gemeentelijke orgaan als zodanig aangewezen plaats in het water al dan niet aangevuld met een op de oever aanwezig terrein of een gedeelte daarvan, die bestemd is voor het permanent afmeren van een vaartuig voor woon-, bedrijfsmatige of recreatieve doeleinden. | K30: Un endroit spécifiquement désigné dans l’eau, complété ou non par un terrain ou une partie de terrain sur la berge, attribué par l’organisme communal compétent et qui est destiné au mouillage permanent d’un navire adapté à des fins résidentielles, commerciales ou recréationnelles. | O30: no
A31: 258 | B31: FED | C31: Location | D31: Class | E31: <http://vocab.belgif.be/ns/location#Municipality> | F31: Municipality | G31: Gemeente | H31: Commune | I31: Official administrative zone of the Belgian territory. The municipality is the smallest administrative part of the Belgian territory whose boundaries can only be changed by the legislator. | J31: Officiële administratieve zone van het Belgisch grondgebied. De gemeente is het kleinste administratieve deel van het Belgisch grondgebied waarvan de grenzen enkel door de wetgever kunnen worden gewijzigd. | K31: Zone administrative officielle du territoire belge. La commune est la plus petite partie administrative du territoire belge dont les limites ne peuvent être modifiées que par le législateur. | O31: no
A32: 260 | B32: FED | C32: Location | D32: Class | E32: <http://vocab.belgif.be/ns/location#Parcel> | F32: Parcel | G32: Perceel | H32: Parcelle | I32: A "parcel" is a part of the territory officially established with a cadastral or administrative purpose. | J32: Een “perceel” is een deel van het grondgebied officieel vastgesteld met een kadastraal of administratief doel. | K32: Une « parcelle » est une portion du territoire officiellement délimitée dans un but cadastral ou administratif. | O32: no
A33: 262 | B33: FED | C33: Location | D33: Class | E33: <PostalDescriptor> | F33: PostalInfo | G33: Postale info | H33: Info de la poste | I33: Information given by the provider of the universal postal service for the identification of a grouping of addresses in a geographical area for postal purposes. | J33: Informatie toegekend door de aanbieder van de universele postdienst voor de identificatie van een groepering van adressen in een geografisch gebied voor postale doeleinden. | K33: Informations fournies par le fournisseur du service postal universel pour l'identification d'un regroupement d'adresses dans une zone géographique à des fins postales. | O33: no
A34: 263 | B34: FED | C34: Location | D34: Class | E34: <http://vocab.belgif.be/ns/location#Stand> | F34: Stand | G34: Standplaats | H34: Emplacement | I34: "Stand": a site or part thereof designated as such by the competent municipal authority and intended for the permanent installation of an area that is not directly and not permanently connected to the earth and suitable for residential, commercial or recreational purposes. | J34: “Standplaats” : een door het bevoegde gemeentelijke orgaan als zodanig aangewezen terrein of gedeelte daarvan dat bestemd is voor het permanent plaatsen van een niet direct en niet duurzaam met de aarde verbonden en voor woon -, bedrijfsmatige, of recreatieve doeleinden geschikte ruimte. | K34: « Emplacement » : un terrain ou une partie de terrain, attribué par l’organisme communal compétent et qui est destiné au stationnement permanent d’un espace, adapté à des fins résidentielles, commerciale ou récréative et qui n’est pas ancré de façon directe et permanente au sol. | O34: no
A35: 267 | B35: FED | C35: Location | D35: Property | E35: <Address.position> | F35: addressPosition | G35: Positie | H35: Position | I35: Position of a characteristic point that represents the position of the address according to a specific specification and includes information about the origin of the position. | J35: Positie van een karakeristiek punt dat de positie van het adres vertegenwoordigt volgens een bepaalde specificatie en inclusief informatie over de herkomst van de positie. | K35: Position d'un point caractéristique qui représente la position de l'adresse en fonction d'une spécification spécifique et inclut des informations sur l'origine de la position. | O35: no
A36: 268 | B36: FED | C36: Location | D36: Property | E36: <http://vocab.belgif.be/ns/location#addressSortField> | F36: addressSortField | G36: Adres sorteerveld | H36: Adresse champs de triage | I36: Transformation of the original house number & bus number (eg addition of leading zeros) so that this can be sorted. | J36: Transformatie van het oorspronkelijk huisnummer&busnummer (bv toevoeging van voorloopnullen) zodat dit kan worden gesorteerd. | K36: Transformation du numéro de maison d'origine et du numéro de bus (par exemple, ajout de zéros à gauche) afin que cela puisse être trié. | O36: no
A37: 269 | B37: FED | C37: Location | D37: Property | E37: <Address.status> | F37: addressStatus | G37: Adres status | H37: Statut d'adresse | I37: Current status of the address. | J37: Actuele toestand van het adres. | K37: État actuel de l'adresse. | O37: no
A38: 272 | B38: FED | C38: Location | D38: Property | E38: <http://www.w3.org/ns/locn#fullAddress> | F38: fullAddress | G38: Volledig adres | H38: Adresse complète | I38: The complete address in one string, whether or not formatted. Avoids errors due to the splitting of the address in its parts. Displays the prescribed sequence of different parts | J38: Het complete adres in één string, al dan niet geformatteerd. Vermijdt fouten tgv het opsplitsen ve adres in zijn onderdelen. Geeft de voorgeschreven volgorde vd verschillende onderdelen weer | K38: L'adresse complète dans une chaîne, formatée ou non. Évite les erreurs dues à la division de l'adresse dans ses parties. Affiche la séquence prescrite de différentes parties | O38: no
A39: 276 | B39: FED | C39: Location | D39: Property | E39: <Address.component> | F39: hasComponent | G39: Heeft onderdeel | H39: Est composé de | I39: Refers to the various components of a Class. E.g. Address (PostalInfo, Street, Municipality) | J39: Verwijst naar de verschillende componenten van een klasse. Bijv. Adres (PostalInfo, Straat, Gemeente) | K39: Fait référence aux divers composants d’une classe. Par exemple. Adresse (PostalInfo, Rue, Municipalité) | L39: BEST datamodel: hasComponent alternative property names to be checked with BEST: hasStreet, hasMunicipality, hasPartOfMunicipality, hasPostalInfo | M39: BEST datamodel: hasComponent | N39: BEST modèle de données: hasComponent | O39: no
A40: 277 | B40: FED | C40: Location | D40: Property | E40: <http://vocab.belgif.be/ns/location#hasRepresentation> | F40: hasRepresentation | G40: Heeft voorstelling | H40: Est representé par | I40: An object is represented by another. E.g. Address has an AddressRepresentation. | J40: Een object wordt vertegenwoordigd door een ander. Bijv. Adres heeft een adresrepresentatie. | K40: Un objet est représenté par un autre. Par exemple: L'adresse a une représentation d'adresse. | O40: no
...

Sheet Draft
A1: Id | B1: Source | C1: Ontology | D1: Type | E1: URI | F1: Name | G1: LabelNL | H1: LabelFR | I1: Definition | J1: DefinitionNL | K1: DefinitionFR | L1: Comment | M1: CommentNL | N1: CommentFR | O1: inOpenApi
A2: 243 | B2: FED | C2: Organization | D2: Property | E2: <http://vocab.belgif.be/ns/organization#authorization> | F2: authorization | G2: Toelating | H2: Autorisation | I2: Authorization allowed by an administration to the company. By authorizations we mean approvals, permits, licenses, ... that can be issued with the intention of carrying out certain activities. | J2: Toelating toegestaan zijn door een administratie aan de onderneming. Onder toelatingen verstaan we erkenningen, vergunningen, licenties, ... die uitgereikt kunnen worden met de bedoeling bepaalde activiteiten te mogen uitvoeren. | K2: Autorisation autorisée par une administration à la société. Par autorisations, nous entendons les approbations, permis, licences, ... pouvant être délivrés dans l’intention de réaliser certaines activités. | O2: no
A3: 261 | B3: FED | C3: Location | D3: Class | E3: <http://vocab.belgif.be/ns/location#PartOfMunicipality> | F3: PartOfMunicipality | G3: Deelgemeente | H3: Sous-municipalité | I3: A part of a municipality, such as a former municipality (prior to the merger of the municipalities), or a neighborhood. | J3: Een deel van een gemeente, zoals een voormalige gemeente (voorafgaand aan de fusie van de gemeenten), of een wijk. | K3: Une partie du territoire d’une commune, telle qu’une ancienne commune (préalable à la fusion des communes) ou un quartier. | L3: Context BEST: Part of Municipality is a class defined by the Walloon region. It does not exist in Flanders nor in the Brussels region. | M3: Context BEST: Een deelgemeente is een klasse gedefinieerd door het Waalse Gewest. Het bestaat niet in Vlaanderen, noch in het Brussels Gewest. | N3: Contexte BEST: Une sous-municipalité est une classe définie par la région wallonne. Elle n'existe pas en Flandre ni en région bruxelloise. | O3: no
A4: 278 | B4: FED | C4: Location | D4: Property | E4: <http://vocab.belgif.be/ns/location#homonymAddition> | F4: homonymAddition | G4: Homoniemtoevoeging | H4: Addition homonyme | I4: Addition to distinguish double street names (street names with the same name but different location in the municipality and their own addresses). | J4: Toevoeging om dubbele straatnamen (straatnamen met dezelfde naam maar andere ligging in de gemeente en eigen adressen) van elkaar te onderscheiden. | K4: Ajout pour distinguer les noms de rues doubles (noms de rues avec le même nom mais emplacement différent dans la municipalité et leurs propres adresses). | L4: See https://github.com/belgif/fedvoc/wiki/Mapping-of-a-Belgian-(BEST)-address-on-an-international-address | M4: Zie https://github.com/belgif/fedvoc/wiki/Mapping-of-a-Belgian-(BEST)-address-on-an-international-address | N4: Voir https://github.com/belgif/fedvoc/wiki/Mapping-of-a-Belgian-(BEST)-address-on-an-international-address | O4: no
A5: 297 | B5: FED | C5: Location | D5: Property | E5: <http://vocab.belgif.be/ns/location#partOfMunicipalityName> | F5: partOfMunicipalityName | G5: Naam deelgemeente | H5: Nom de la sous-municipalité | I5: Name of the part of the municipality | J5: Naam van de deelgemeente | K5: Nom de la partie de la commune | L5: Context BEST: Part of Municipality is a class defined by the Walloon region. It does not exist in Flanders nor in the Brussels region. See https://github.com/belgif/fedvoc/wiki/Mapping-of-a-Belgian-(BEST)-address-on-an-international-address | M5: Context BEST: Een deelgemeente is een klasse gedefinieerd door het Waalse Gewest. Het bestaat niet in Vlaanderen, noch in het Brussels Gewest. Zie https://github.com/belgif/fedvoc/wiki/Mapping-of-a-Belgian-(BEST)-address-on-an-international-address | N5: Contexte BEST: Une sous-municipalité est une classe définie par la région wallonne. Elle n'existe pas en Flandre ni en région bruxelloise. Voir https://github.com/belgif/fedvoc/wiki/Mapping-of-a-Belgian-(BEST)-address-on-an-international-address | O5: no
A6: 299 | B6: FED | C6: Location | D6: Property | E6: <http://vocab.belgif.be/ns/location#pointGeometry> | F6: pointGeometry | G6: Geometrisch punt | H6: Point géométrique | I6: The cartographic coordinates of the point. | J6: De cartografische coordinaten van het punt. | K6: Les coordonnées cartographiques du point. | O6: no
A7: 337 | B7: FED | C7: Person | D7: Property | E7: <http://vocab.belgif.be/ns/person#headOf> | F7: headOf | G7: Hoofd van | H7: Chef de | I7: Person who represents the household by default. | J7: Persoon die standaard het gezin vertegenwoordigt. | K7: Personne qui représente le ménage par défaut. | O7: no
A8: 341 | B8: FED | C8: Person | D8: Property | E8: <http://vocab.belgif.be/ns/person#memberOf> | F8: memberOf | G8: Lid van | H8: Membre de | I8: Person who belongs to a household. | J8: Persoon die tot een gezin behoort. | K8: Personne qui appartient à un ménage. | O8: no
A9: 343 | B9: FED | C9: Person | D9: Property | E9: <http://vocab.belgif.be/ns/person#nationality> | F9: nationality | G9: Nationaliteit | H9: Nationalité | I9: The relationship between a person and a state, culture or loyalty. Note that this concept is broader than citizenship (which is limited to the relationship with a state). Anyone who has the nationality of a particular country is usually automatically a citizen. Nationality is usually obtained automatically by birth: one gets either the nationality of his parents or one gets the vv country where one is a Resident. One can also obtain a certain nationality through naturalization. In principle, people lose their original nationality, but that is not always the case (multiple nationality). | J9: De relatie tussen een persoon en een staat, cultuur of loyaliteit. Merk op dat dit begrip ruimer is dan staatsburgerschap (dat zich beperkt tot de relatie met een staat). Wie de nationaliteit ve bepaald land heeft is er doorgaans ook automatisch staatsburger van. Nationaliteit wordt doorgaans autamatisch verkregen door geboorte: men krijgt hetzij de nationaliteit van zijn ouders of men krijgt deze vh land waar men Inwoner van is. Men kan een bepaalde nationaliteit ook verkrijgen door naturalisatie. In principe verliest men dan zijn oorspronkelijke nationaliteit, maar dat is niet altijd zo (meervoudige nationaliteit). | K9: La relation entre une personne et un État, la culture ou la loyauté. Notez que ce concept est plus large que la citoyenneté (qui se limite à la relation avec un État). Quiconque a la nationalité d'un pays particulier est généralement automatiquement citoyen. La nationalité est généralement obtenue automatiquement à la naissance: on obtient soit la nationalité de ses parents, soit on obtient le pays où on est résident. On peut aussi obtenir une certaine nationalité par naturalisation. En principe, les personnes perdent leur nationalité d'origine, mais ce n'est pas toujours le cas (pluralité de nationalités). | O9: no
A10: 348 | B10: FED | C10: Person | D10: Property | E10: <http://vocab.belgif.be/ns/person#residenceAddress> | F10: residenceAddress | G10: Adres hoofdverblijf | H10: Adresse de résidence | I10: Place where a person lives or stays temporarily. | J10: Plaats waar een persoon woont of logeert. | K10: Lieu où une personne vit ou reste temporairement. | O10: no
A11: 359 | B11: FED | C11: Location | D11: Class | E11: <http://vocab.belgif.be/ns/location#GM_Point> | F11: GM_Point | G11: GM_Point | H11: GM_Point | I11: GM_Point is the basic data type for a geometric object consisting of one and only one point. | J11: GM_Point is het elementaire gegevenstype voor een meetkundig object bestaande uit één en slechts één punt. | K11: GM_Point est le type de données de base pour un objet géométrique consistant en un et un seul point. | L11: http://inspire-regadmin.jrc.ec.europa.eu/dataspecification/ScopeObjectDetail.action?objectDetailId=11377 | M11: http://inspire-regadmin.jrc.ec.europa.eu/dataspecification/ScopeObjectDetail.action?objectDetailId=11377 | N11: http://inspire-regadmin.jrc.ec.europa.eu/dataspecification/ScopeObjectDetail.action?objectDetailId=11377 | O11: no
A12: 360 | B12: FED | C12: Location | D12: ConceptScheme | E12: <http://vocab.belgif.be/auth/addressstatus> | F12: AddressStatus | G12: Status adres | H12: Statut d'adresse | I12: Conceptscheme with possible status values for a BEST address. | J12: Conceptscheme met mogelijke statuswaarden voor een BEST-adres. | K12: Conceptscheme avec les valeurs d'état possibles pour une adresse BEST. | O12: no
A13: 361 | B13: FED | C13: Person | D13: ConceptScheme | E13: <http://vocab.belgif.be/auth/administrativestatus> | F13: AdministrativeStatus | G13: Administratieve status | H13: Statut administratif | I13: Conceptscheme with the values of an administrative status. | J13: Conceptscheme met de waarden van een administratieve status. | K13: Statut administratif. | O13: no
A14: 363 | B14: FED | C14: Person | D14: ConceptScheme | E14: <http://vocab.belgif.be/auth/descent> | F14: Descent | G14: Afstamming | H14: Descendance | I14: Conceptscheme with the values for the descent of a person. Descent is the descending line of blood relationship between different generations. The descent can also be non-biological, eg adoption. Descent can also be viewed in the ascending line. The concept is scarier than kinship that also includes marriage. | J14: Conceptscheme met de waarden voor de afstamming van een persoon. Afstamming is de dalende lijn van bloedverwantschap tussen verschillende generaties. De afstamming kan ook niet-biologisch zijn, bv adoptie. Afstamming kan ook in opgaande lijn worden bekeken. Het begrip is enger dan verwantschap dat oa ook huwelijk inhoudt. | K14: Conceptscheme avec les valeurs pour la descendance d'une personne. La descendance est la relation descendante entre les différentes générations. La descendance peut également être non biologique, par exemple l'adoption. La descendance peut également être vue dans la ligne ascendante. Le concept est plus effrayant que la parenté qui inclut également le mariage. | L14: CONCEPTSCHEME DEFINITION to be done | M14: CONCEPTSCHEME DEFINITION to do | N14: CONCEPTSCHEME DEFINITION to do | O14: no
A15: 653 | B15: FED | C15: Location | D15: Property | E15: <http://www.w3.org/ns/locn#addressArea> | F15: addressArea | G15: Adresgebied | H15: Zone d'adresse | I15: The name or names of a geographic area or locality that groups a number of addressable objects for addressing purposes, without being an administrative unit. This would typically be part of a city, a neighbourhood or village. | J15: De naam of namen van een geografisch gebied of een geografische locatie die een aantal adresseerbare objecten groepeert voor adresdoeleinden, zonder een administratieve eenheid te zijn. Dit zou typisch onderdeel zijn van een stad, een buurt of een dorp. | K15: Le ou les noms d'une zone géographique ou d'une localité regroupant un certain nombre d'objets adressables à des fins d'adressage, sans être une unité administrative. Cela ferait typiquement partie d'une ville, d'un quartier ou d'un village. | O15: no
A16: 654 | B16: FED | C16: Location | D16: Property | E16: <http://www.w3.org/ns/locn#locatorName> | F16: locatorName | G16: Locatienaam | H16: Nom de la localisation | I16: Proper noun(s) applied to the real world entity identified by the locator. The locator name could be the name of the property or complex, of the building or part of the building, or it could be the name of a room inside a building. | J16: Naam toegepast op de entiteit in de echte wereld geïdentificeerd door de locator. De locatornaam kan de naam zijn van het pand of complex, van het gebouw of een deel van het gebouw, of het kan de naam zijn van een kamer in een gebouw. | K16: Nom (s) approprié (s) appliqué (s) à l'entité du monde réel identifiée par le localisateur. Le nom du localisateur pourrait être le nom de la propriété ou du complexe, du bâtiment ou d’une partie du bâtiment, ou le nom d’une pièce à l’intérieur d’un bâtiment. | O16: no
A17: 674 | B17: FED | C17: Person | D17: Property | E17: <http://www.w3.org/ns/person#residency> | F17: residency | G17: Resident van | H17: Résident de | I17: Residency typically provides an individual with a subset of the rights of a citizen. | J17: Residentie (inwonerschap) biedt een individu typisch een deelverzameling van de rechten van een burger. | K17: La résidence fournit généralement à un individu un sous-ensemble des droits d'un citoyen. | O17: no
A18: 675 | B18: FED | C18: Person | D18: Property | E18: <http://www.w3.org/ns/person#citizenship> | F18: citizenship | G18: Burger van | H18: Citoyen de | I18: The citizenship relationship links a Person to a Jurisdiction that has conferred citizenship rights on the individual such as the right to vote, to receive certain protection from the community or the issuance of a passport. Multiple citizenships are recorded as multiple instances of the citizenship relationship. | J18: De burgerschapsrelatie (staatsburgerschap) verbindt een persoon met een rechtsgebied dat burgerschapsrechten heeft verleend aan het individu, zoals het stemrecht, bepaalde bescherming van de gemeenschap of de uitgifte van een paspoort. Meer nationaliteiten worden geregistreerd als meer instanties van de relatie tussen staatsburgerschap. | K18: La relation de citoyenneté lie une personne à une juridiction qui lui a conféré des droits, tels que le droit de voter, le droit de recevoir une certaine protection de la communauté ou la délivrance d'un passeport. Les citoyennetés multiples sont enregistrées en tant qu'exemples multiples de la relation de citoyenneté. | O18: no
A19: 676 | B19: FED | C19: Person | D19: Class | E19: <http://purl.org/dc/terms/Jurisdiction> | F19: Jurisdiction | G19: Jurisdictie | H19: Juridiction | I19: The extent or range of judicial, law enforcement, or other authority. | J19: De omvang of het bereik van juridische, wetshandhaving of andere autoriteit. | K19: L'étendue ou la gamme des autorités judiciaires, des forces de l'ordre ou autres. | O19: no
A20: 682 | B20: FED | C20: Organization | D20: Property | E20: <http://vocab.belgif.be/auth/quality> | F20: quality | G20: hoedanigheid | H20: qualité | I20: A qualities is allowed by the administration to a company. A quality that the company is known to, can be VAT-liable, "Employer"... The quality can be in different stages: 'in application', 'refused', 'awarded', ... | J20: Een hoedanigheid is door de administratie toegestaan aan een bedrijf. Het gaat om hoedanigheden waaronder de onderneming gekend is, zoals 'BTW-plichtige’, ‘Werkgever’. De hoedanigheid kan zich in verschillende stadia bevinden: 'in aanvraag', 'geweigerd', 'toegekend', ... | K20: Une qualité est autorisée par l'administration à l'entreprise. Ce sont des qualités que l’entreprise connaît, telles que «assujetti à la TVA», «employeur». La qualité peut être à différentes étapes: "en application", "refusée", "attribuée", ... | O20: no
A21: 683 | B21: FED | C21: Person | D21: Property | E21: <http://vocab.belgif.be/ns/person#administrativeStatus> | F21: administrativeStatus | G21: administratieve status | H21: statut administratif | I21: Administrative status. | J21: Administratieve status. | K21: Conceptscheme avec les valeurs d'un statut administratif. | O21: no
A22: 696 | B22: FED | C22: Other | D22: Property | E22: <identifier> | F22: plateNumber | G22: Nummerplaat | H22: Plaque d'immatriculation | I22: Recommended best practice is to identify the resource by means of a string conforming to a formal identification system. An unambiguous reference to the resource within a given context. | J22: Aanbevolen beste praktijk is om de bron te identificeren door middel van een string die overeenkomt met een formeel identificatiesysteem. Een eenduidige verwijzing naar de bron binnen een bepaalde context. | K22: La meilleure pratique recommandée consiste à identifier la ressource à l'aide d'une chaîne conforme à un système d'identification formel. Une référence non ambiguë à la ressource dans un contexte donné. | L22: The official set of numbers and letters shown on the front and back of a road vehicle | M22: De officiële reeks cijfers en letters op de voor- en achterkant van een wegvoertuig | N22: L'ensemble officiel de chiffres et de lettres figurant à l'avant et à l'arrière d'un véhicule routier | O22: no
A23: 697 | B23: FED | C23: Other | D23: Property | E23: <identifier> | F23: ipAddress | G23: IP-adres | H23: Adresse IP | I23: Recommended best practice is to identify the resource by means of a string conforming to a formal identification system. An unambiguous reference to the resource within a given context. | J23: Aanbevolen beste praktijk is om de bron te identificeren door middel van een string die overeenkomt met een formeel identificatiesysteem. Een eenduidige verwijzing naar de bron binnen een bepaalde context. | K23: La meilleure pratique recommandée consiste à identifier la ressource à l'aide d'une chaîne conforme à un système d'identification formel. Une référence non ambiguë à la ressource dans un contexte donné. | L23: An Internet Protocol address (IP address) is a numerical label assigned to each device connected to a computer network that uses the Internet Protocol for communication. | M23: Een internetprotocoladres (IP-adres) is een numeriek label dat wordt toegewezen aan elk apparaat dat is aangesloten op een computernetwerk dat het internetprotocol gebruikt voor communicatie. | N23: Une adresse de protocole Internet (adresse IP) est une étiquette numérique attribuée à chaque périphérique connecté à un réseau informatique qui utilise le protocole Internet pour la communication. | O23: no
A24: 710 | B24: FED | C24: Location | D24: Class | E24: <http://vocab.belgif.be/ns/location#Country> | F24: Country | G24: Land | H24: Pays | I24: A country is a political state, nation, or territory which is controlled. It is often referred to as the land of an individual's birth, residence, or citizenship. | J24: Een land is een politieke staat, natie of territorium dat wordt gecontroleerd. Het wordt vaak het land van iemands geboorte, verblijf of staatsburgerschap genoemd. | K24: Un pays est un État, une nation ou un territoire politique qui est contrôlé. On l'appelle souvent le pays de naissance, de résidence ou de citoyenneté d'un individu. | O24: no
A25: 713 | B25: FED | C25: Location | D25: ConceptScheme | E25: <http://vocab.belgif.be/auth/municipalitycode> | F25: MunicipalityCode | G25: NIS code gemeente | H25: Code commune NIS | I25: The conceptscheme "MunicipalityCode" contains municipalities represented by a NIS code. | J25: Het conceptschema "GemeenteCode" bevat gemeenten die worden weergegeven door een NIS-code. | K25: Le schéma de concepts "MunicipalityCode" contient des municipalités représentées par un code NIS. | O25: no
A26: 741 | B26: FED | C26: Location | D26: Property | E26: <identifier> | F26: bestIdentifier | G26: BEST identifier | H26: Identifiant BEST | I26: Identifier of a BEST address or a BEST address component. | J26: Identifier van een BEST-adres of een BEST-adrescomponent. | K26: Identifiant d'une adresse BEST ou d'un composant d'adresse BEST. | L26: BEST = Belgian Streets and Addresses, a standard for Belgian addresses and address components. Address component = Municipality, PostalInfo, PartOfMunicipality, Streetname A BEST identifier consists of a namespace, an object identifier and a version. | M26: BEST = Belgian Streets and Addresses, een standaard voor Belgische adressen en adrescomponenten. Adrescomponent = Gemeente, PostInfo, PartOfMunicipality, Straatnaam Een BEST-identifier bestaat uit een naamruimte, een object-identifier en een versie. | N26: BEST = Belgian Streets and Addresses, un standard pour les adresses et composants d'adresses belges. Composant d'adresse = Municipalité, PostalInfo, PartOfMunicipality, Streetname Un identifiant BEST se compose d'un espace de noms, d'un identifiant d'objet et d'une version. | O26: no
A27: 745 | B27: FED | C27: Other | D27: Property | E27: <http://vocab.belgif.be/ns/other#preferredLanguage> | F27: preferredLanguage | G27: Voorkeurtaal | H27: Langue préférée | I27: Language that an agent wants to use preferrably in his contacts with another agent. | J27: Taal die een agent bij voorkeur wil gebruiken in zijn contacten met een andere agent. | K27: Langue qu'un agent souhaite utiliser de préférence dans ses contacts avec un autre agent. | O27: no
A28: 748 | B28: FED | C28: Person | D28: Property | E28: <http://vocab.belgif.be/auth/community> | F28: community | G28: Gemeenschap | H28: Communauté | I28: Concept corresponding to a community code in Belgium. | J28: Concept dat overeenkomt met een gemeenschapscode in België. | K28: Concept correspondant à un code communautaire en Belgique. | L28: See CommunityCode | M28: Zie CommunityCode | N28: Voir CommunityCode | O28: no

Sheet ChangeLog
A1: Date | B1: CAUD | C1: Id | D1: StatusUpdate | E1: Name | F1: OldName | G1: Status | H1: Ontology | I1: Type | J1: Comment
A2: 45310 | B2: Add | C2: 732 | E2: =IF(OR(Table11[[#This Row],[CAUD]]="Add", Table11[[#This Row],[CAUD]]="Update"),VLOOKUP(Table11[[#This Row],[Id]],Table1[#All],2,),"") -> Nationality | G2: =IF(OR(Table11[[#This Row],[CAUD]]="Add", Table11[[#This Row],[CAUD]]="Update"),VLOOKUP(Table11[[#This Row],[Id]],Table6[#All],8,),"") -> Proposed standard | H2: =IF(OR(Table11[[#This Row],[CAUD]]="Add", Table11[[#This Row],[CAUD]]="Update"),VLOOKUP(Table11[[#This Row],[Id]],Table1[#All],4,),"") -> Location | I2: =IF(OR(Table11[[#This Row],[CAUD]]="Add", Table11[[#This Row],[CAUD]]="Update"),VLOOKUP(Table11[[#This Row],[Id]],Table1[#All],5,),"") -> ConceptScheme
A3: 45310 | B3: Add | C3: 733 | E3: Country | J3: Country has multiple ConceptScheme implementations.
A4: 45310 | B4: Comment | E4: =IF(OR(Table11[[#This Row],[CAUD]]="Add", Table11[[#This Row],[CAUD]]="Update"),VLOOKUP(Table11[[#This Row],[Id]],Table1[#All],2,),"") | G4: =IF(OR(Table11[[#This Row],[CAUD]]="Add", Table11[[#This Row],[CAUD]]="Update"),VLOOKUP(Table11[[#This Row],[Id]],Table6[#All],8,),"") | H4: =IF(OR(Table11[[#This Row],[CAUD]]="Add", Table11[[#This Row],[CAUD]]="Update"),VLOOKUP(Table11[[#This Row],[Id]],Table1[#All],4,),"") | I4: =IF(OR(Table11[[#This Row],[CAUD]]="Add", Table11[[#This Row],[CAUD]]="Update"),VLOOKUP(Table11[[#This Row],[Id]],Table1[#All],5,),"") | J4: Introduction of Datatypes + updated Datamodels sheet
A5: 45310 | B5: Delete | C5: 365 | E5: =IF(OR(Table11[[#This Row],[CAUD]]="Add", Table11[[#This Row],[CAUD]]="Update"),VLOOKUP(Table11[[#This Row],[Id]],Table1[#All],2,),"") | F5: TerritoryOfNationality | G5: =IF(OR(Table11[[#This Row],[CAUD]]="Add", Table11[[#This Row],[CAUD]]="Update"),VLOOKUP(Table11[[#This Row],[Id]],Table6[#All],8,),"") | H5: =IF(OR(Table11[[#This Row],[CAUD]]="Add", Table11[[#This Row],[CAUD]]="Update"),VLOOKUP(Table11[[#This Row],[Id]],Table1[#All],4,),"") | I5: =IF(OR(Table11[[#This Row],[CAUD]]="Add", Table11[[#This Row],[CAUD]]="Update"),VLOOKUP(Table11[[#This Row],[Id]],Table1[#All],5,),"")
